<?xml version="1.0" encoding="utf-8"?>
<!-- This URDF was automatically created by SolidWorks to URDF Exporter! Originally created by Stephen Brawner (brawner@gmail.com) 
     Commit Version: 1.6.0-4-g7f85cfe  Build Version: 1.6.7995.38578
     For more information, please see http://wiki.ros.org/sw_urdf_exporter -->
<robot
  name="mz07l">
  <link
    name="base_link">
    <inertial>
      <origin
        xyz="-0.0339413550611 -2.31586087358626E-05 0.0999304628614501"
        rpy="0 0 0" />
      <mass
        value="7.48699011088476" />
      <inertia
        ixx="0.0388213139945611"
        ixy="1.55653817415135E-05"
        ixz="-0.00111870477566242"
        iyy="0.0609468745248538"
        iyz="1.10362007676236E-05"
        izz="0.0543745416553623" />
    </inertial>
    <visual>
      <origin
        xyz="0 0 0"
        rpy="0 0 0" />
      <geometry>
        <mesh
          filename="package://mz07l/meshes/base_link.STL" />
      </geometry>
      <material
        name="">
        <color
          rgba="1 1 1 1" />
      </material>
    </visual>
    <collision>
      <origin
        xyz="0 0 0"
        rpy="0 0 0" />
      <geometry>
        <mesh
          filename="package://mz07l/meshes/base_link.STL" />
      </geometry>
    </collision>
  </link>
  <link
    name="Link1">
    <inertial>
      <origin
        xyz="0.014841 1.5699E-05 0.081192"
        rpy="0 0 0" />
      <mass
        value="4.412" />
      <inertia
        ixx="0.035899"
        ixy="5.2201E-07"
        ixz="-0.0047926"
        iyy="0.023641"
        iyz="-8.4594E-06"
        izz="0.030311" />
    </inertial>
    <visual>
      <origin
        xyz="0 0 0"
        rpy="0 0 0" />
      <geometry>
        <mesh
          filename="package://mz07l/meshes/Link1.STL" />
      </geometry>
      <material
        name="">
        <color
          rgba="1 1 1 1" />
      </material>
    </visual>
    <collision>
      <origin
        xyz="0 0 0"
        rpy="0 0 0" />
      <geometry>
        <mesh
          filename="package://mz07l/meshes/Link1.STL" />
      </geometry>
    </collision>
  </link>
  <joint
    name="J1"
    type="revolute">
    <origin
      xyz="0 0 0.197"
      rpy="0 0 0" />
    <parent
      link="base_link" />
    <child
      link="Link1" />
    <axis
      xyz="0 0 -1" />
    <limit
      lower="-2.97"
      upper="2.97"
      effort="100"
      velocity="1" />
  </joint>
  <link
    name="Link2">
    <inertial>
      <origin
        xyz="-0.032892 -0.19917 -0.00011311"
        rpy="0 0 0" />
      <mass
        value="6.848" />
      <inertia
        ixx="0.14404"
        ixy="-0.013206"
        ixz="2.2979E-05"
        iyy="0.031526"
        iyz="0.00015771"
        izz="0.12908" />
    </inertial>
    <visual>
      <origin
        xyz="0 0 0"
        rpy="0 0 0" />
      <geometry>
        <mesh
          filename="package://mz07l/meshes/Link2.STL" />
      </geometry>
      <material
        name="">
        <color
          rgba="1 1 1 1" />
      </material>
    </visual>
    <collision>
      <origin
        xyz="0 0 0"
        rpy="0 0 0" />
      <geometry>
        <mesh
          filename="package://mz07l/meshes/Link2.STL" />
      </geometry>
    </collision>
  </link>
  <joint
    name="J2"
    type="revolute">
    <origin
      xyz="0.05549 0 0.15313"
      rpy="-1.5708 0 0" />
    <parent
      link="Link1" />
    <child
      link="Link2" />
    <axis
      xyz="0 0 -1" />
    <limit
      lower="-2.36"
      upper="1.40"
      effort="100"
      velocity="1" />
  </joint>
  <link
    name="Link3">
    <inertial>
      <origin
        xyz="-0.0090499 -0.020552 -0.00035078"
        rpy="0 0 0" />
      <mass
        value="2.9258" />
      <inertia
        ixx="0.0079804"
        ixy="0.00090576"
        ixz="-2.4093E-05"
        iyy="0.010878"
        iyz="4.0089E-05"
        izz="0.013867" />
    </inertial>
    <visual>
      <origin
        xyz="0 0 0"
        rpy="0 0 0" />
      <geometry>
        <mesh
          filename="package://mz07l/meshes/Link3.STL" />
      </geometry>
      <material
        name="">
        <color
          rgba="1 1 1 1" />
      </material>
    </visual>
    <collision>
      <origin
        xyz="0 0 0"
        rpy="0 0 0" />
      <geometry>
        <mesh
          filename="package://mz07l/meshes/Link3.STL" />
      </geometry>
    </collision>
  </link>
  <joint
    name="J3"
    type="revolute">
    <origin
      xyz="-0.043963 -0.40764 0.0005"
      rpy="0 0 -0.10743" />
    <parent
      link="Link2" />
    <child
      link="Link3" />
    <axis
      xyz="0 0 -1" />
    <limit
      lower="-2.43"
      upper="4.71"
      effort="100"
      velocity="1" />
  </joint>
  <link
    name="Link4">
    <inertial>
      <origin
        xyz="0.00015954 0.00087417 -0.18756"
        rpy="0 0 0" />
      <mass
        value="3.6583" />
      <inertia
        ixx="0.036368"
        ixy="1.7012E-05"
        ixz="-1.3478E-05"
        iyy="0.034763"
        iyz="-0.00043475"
        izz="0.0075828" />
    </inertial>
    <visual>
      <origin
        xyz="0 0 0"
        rpy="0 0 0" />
      <geometry>
        <mesh
          filename="package://mz07l/meshes/Link4.STL" />
      </geometry>
      <material
        name="">
        <color
          rgba="1 1 1 1" />
      </material>
    </visual>
    <collision>
      <origin
        xyz="0 0 0"
        rpy="0 0 0" />
      <geometry>
        <mesh
          filename="package://mz07l/meshes/Link4.STL" />
      </geometry>
    </collision>
  </link>
  <joint
    name="J4"
    type="revolute">
    <origin
      xyz="0.44 -0.044808 0"
      rpy="1.5708 0 1.5708" />
    <parent
      link="Link3" />
    <child
      link="Link4" />
    <axis
      xyz="0 0 -1" />
    <limit
      lower="-3.32"
      upper="3.32"
      effort="100"
      velocity="1" />
  </joint>
  <link
    name="Link5">
    <inertial>
      <origin
        xyz="0.0230406181638934 2.08510693291419E-05 -0.00447853212657651"
        rpy="0 0 0" />
      <mass
        value="0.394276330704897" />
      <inertia
        ixx="0.000415412041832548"
        ixy="-1.54162941581748E-08"
        ixz="-4.17402909160816E-05"
        iyy="0.000538362833357643"
        iyz="-6.30830998657262E-07"
        izz="0.00049121106760061" />
    </inertial>
    <visual>
      <origin
        xyz="0 0 0"
        rpy="0 0 0" />
      <geometry>
        <mesh
          filename="package://mz07l/meshes/Link5.STL" />
      </geometry>
      <material
        name="">
        <color
          rgba="1 1 1 1" />
      </material>
    </visual>
    <collision>
      <origin
        xyz="0 0 0"
        rpy="0 0 0" />
      <geometry>
        <mesh
          filename="package://mz07l/meshes/Link5.STL" />
      </geometry>
    </collision>
  </link>
  <joint
    name="J5"
    type="revolute">
    <origin
      xyz="0 0 0"
      rpy="1.5708 -1.5708 0" />
    <parent
      link="Link4" />
    <child
      link="Link5" />
    <axis
      xyz="0 0 -1" />
    <limit
      lower="-2.09"
      upper="2.09"
      effort="100"
      velocity="1" />
  </joint>
  <link
    name="Link6">
    <inertial>
      <origin
        xyz="-0.000274575549283895 -7.3596587501723E-05 0.0700828204222902"
        rpy="0 0 0" />
      <mass
        value="0.0303019437346346" />
      <inertia
        ixx="1.15411086776968E-05"
        ixy="7.12436535151465E-08"
        ixz="-9.30040373570713E-09"
        iyy="1.10884190423027E-05"
        iyz="-2.47999052156489E-09"
        izz="2.14713687887249E-05" />
    </inertial>
    <visual>
      <origin
        xyz="0 0 0"
        rpy="0 0 0" />
      <geometry>
        <mesh
          filename="package://mz07l/meshes/Link6.STL" />
      </geometry>
      <material
        name="">
        <color
          rgba="1 1 1 1" />
      </material>
    </visual>
    <collision>
      <origin
        xyz="0 0 0"
        rpy="0 0 0" />
      <geometry>
        <mesh
          filename="package://mz07l/meshes/Link6.STL" />
      </geometry>
    </collision>
  </link>
  <joint
    name="J6"
    type="revolute">
    <origin
      xyz="0 0 0"
      rpy="1.5708 0 1.5708" />
    <parent
      link="Link5" />
    <child
      link="Link6" />
    <axis
      xyz="0 0 -1" />
    <limit
      lower="-6.28"
      upper="6.28"
      effort="100"
      velocity="1" />
  </joint>
  <link
    name="Tool">
    <inertial>
      <origin
        xyz="-0.000274575549283895 -7.35965875017786E-05 -0.00291717957770976"
        rpy="0 0 0" />
      <mass
        value="0.0303019437346346" />
      <inertia
        ixx="1.15411086776968E-05"
        ixy="7.12436535151464E-08"
        ixz="-9.30040373568712E-09"
        iyy="1.10884190423027E-05"
        iyz="-2.47999052156478E-09"
        izz="2.14713687887249E-05" />
    </inertial>
    <visual>
      <origin
        xyz="0 0 0"
        rpy="0 0 0" />
      <geometry>
        <mesh
          filename="package://mz07l/meshes/Tool.STL" />
      </geometry>
      <material
        name="">
        <color
          rgba="1 1 1 1" />
      </material>
    </visual>
    <collision>
      <origin
        xyz="0 0 0"
        rpy="0 0 0" />
      <geometry>
        <mesh
          filename="package://mz07l/meshes/Tool.STL" />
      </geometry>
    </collision>
  </link>
  <joint
    name="J7"
    type="fixed">
    <origin
      xyz="0 0 0.073"
      rpy="0 0 0" />
    <parent
      link="Link6" />
    <child
      link="Tool" />
    <axis
      xyz="0 0 0" />
  </joint>
</robot>