<?xml version="1.0" encoding="utf-8"?>
<!-- This URDF was automatically created by SolidWorks to URDF Exporter! Originally created by Stephen Brawner (brawner@gmail.com) 
     Commit Version: 1.6.0-4-g7f85cfe  Build Version: 1.6.7995.38578
     For more information, please see http://wiki.ros.org/sw_urdf_exporter -->
<robot
  name="mz07l">
  <link
    name="base_link">
    <inertial>
      <origin
        xyz="-0.0339413550611 -2.31586087358071E-05 0.0999304628614501"
        rpy="0 0 0" />
      <mass
        value="7.48699011088476" />
      <inertia
        ixx="0.0388213139945611"
        ixy="1.55653817415242E-05"
        ixz="-0.00111870477566243"
        iyy="0.0609468745248538"
        iyz="1.10362007676289E-05"
        izz="0.0543745416553623" />
    </inertial>
    <visual>
      <origin
        xyz="0 0 0"
        rpy="0 0 0" />
      <geometry>
        <mesh
          filename="package://mz07l/meshes/base_link.STL" />
      </geometry>
      <material
        name="">
        <color
          rgba="1 1 1 1" />
      </material>
    </visual>
    <collision>
      <origin
        xyz="0 0 0"
        rpy="0 0 0" />
      <geometry>
        <mesh
          filename="package://mz07l/meshes/base_link.STL" />
      </geometry>
    </collision>
  </link>
  <link
    name="base">
    <inertial>
      <origin
        xyz="-0.0339413550611 -2.31586087358071E-05 0.0999304628614501"
        rpy="0 0 0" />
      <mass
        value="7.48699011088476" />
      <inertia
        ixx="0.0388213139945611"
        ixy="1.55653817415241E-05"
        ixz="-0.00111870477566243"
        iyy="0.0609468745248538"
        iyz="1.10362007676287E-05"
        izz="0.0543745416553623" />
    </inertial>
    <visual>
      <origin
        xyz="0 0 0"
        rpy="0 0 0" />
      <geometry>
        <mesh
          filename="package://mz07l/meshes/base.STL" />
      </geometry>
      <material
        name="">
        <color
          rgba="1 1 1 1" />
      </material>
    </visual>
    <collision>
      <origin
        xyz="0 0 0"
        rpy="0 0 0" />
      <geometry>
        <mesh
          filename="package://mz07l/meshes/base.STL" />
      </geometry>
    </collision>
  </link>
  <joint
    name="J0"
    type="fixed">
    <origin
      xyz="0 0 0"
      rpy="0 0 0" />
    <parent
      link="base_link" />
    <child
      link="base" />
    <axis
      xyz="0 0 0" />
  </joint>
  <link
    name="Link1">
    <inertial>
      <origin
        xyz="0.014841210559779 1.5699038155903E-05 0.0811924353570906"
        rpy="0 0 0" />
      <mass
        value="4.4119668882482" />
      <inertia
        ixx="0.0358985469586784"
        ixy="5.22005399590224E-07"
        ixz="-0.0047925881900029"
        iyy="0.0236405205772908"
        iyz="-8.45938545831362E-06"
        izz="0.0303112529475369" />
    </inertial>
    <visual>
      <origin
        xyz="0 0 0"
        rpy="0 0 0" />
      <geometry>
        <mesh
          filename="package://mz07l/meshes/Link1.STL" />
      </geometry>
      <material
        name="">
        <color
          rgba="1 1 1 1" />
      </material>
    </visual>
    <collision>
      <origin
        xyz="0 0 0"
        rpy="0 0 0" />
      <geometry>
        <mesh
          filename="package://mz07l/meshes/Link1.STL" />
      </geometry>
    </collision>
  </link>
  <joint
    name="J1"
    type="revolute">
    <origin
      xyz="0 0 0.197"
      rpy="0 0 0" />
    <parent
      link="base" />
    <child
      link="Link1" />
    <axis
      xyz="0 0 -1" />
    <limit
      lower="-2.97"
      upper="2.97"
      effort="100"
      velocity="5.24" />
  </joint>
  <link
    name="Link2">
    <inertial>
      <origin
        xyz="-0.011346 -0.20155 -0.00011313"
        rpy="0 0 0" />
      <mass
        value="6.848" />
      <inertia
        ixx="0.14556"
        ixy="-0.00090711"
        ixz="5.9383E-06"
        iyy="0.030004"
        iyz="0.00015927"
        izz="0.12908" />
    </inertial>
    <visual>
      <origin
        xyz="0 0 0"
        rpy="0 0 0" />
      <geometry>
        <mesh
          filename="package://mz07l/meshes/Link2.STL" />
      </geometry>
      <material
        name="">
        <color
          rgba="1 1 1 1" />
      </material>
    </visual>
    <collision>
      <origin
        xyz="0 0 0"
        rpy="0 0 0" />
      <geometry>
        <mesh
          filename="package://mz07l/meshes/Link2.STL" />
      </geometry>
    </collision>
  </link>
  <joint
    name="J2"
    type="revolute">
    <origin
      xyz="0.05 0 0.148"
      rpy="-1.5708 0 0" />
    <parent
      link="Link1" />
    <child
      link="Link2" />
    <axis
      xyz="0 0 -1" />
    <limit
      lower="-2.36"
      upper="1.40"
      effort="100"
      velocity="4.89" />
  </joint>
  <link
    name="Link3">
    <inertial>
      <origin
        xyz="-0.00904991070713413 -0.0205515465689395 -0.000350779118959976"
        rpy="0 0 0" />
      <mass
        value="2.92582891160545" />
      <inertia
        ixx="0.00798036496861194"
        ixy="0.000905760336948981"
        ixz="-2.40936433332828E-05"
        iyy="0.0108776733436978"
        iyz="4.00887085723535E-05"
        izz="0.0138666321003948" />
    </inertial>
    <visual>
      <origin
        xyz="0 0 0"
        rpy="0 0 0" />
      <geometry>
        <mesh
          filename="package://mz07l/meshes/Link3.STL" />
      </geometry>
      <material
        name="">
        <color
          rgba="1 1 1 1" />
      </material>
    </visual>
    <collision>
      <origin
        xyz="0 0 0"
        rpy="0 0 0" />
      <geometry>
        <mesh
          filename="package://mz07l/meshes/Link3.STL" />
      </geometry>
    </collision>
  </link>
  <joint
    name="J3"
    type="revolute">
    <origin
      xyz="0 -0.41 0"
      rpy="0 0 0" />
    <parent
      link="Link2" />
    <child
      link="Link3" />
    <axis
      xyz="0 0 -1" />
    <limit
      lower="-1.169"
      upper="3.316"
      effort="100"
      velocity="6.28" />
  </joint>
  <link
    name="Link4">
    <inertial>
      <origin
        xyz="0.00015954 0.00087409 -0.18756"
        rpy="0 0 0" />
      <mass
        value="3.6583" />
      <inertia
        ixx="0.036368"
        ixy="1.7015E-05"
        ixz="-1.3434E-05"
        iyy="0.034763"
        iyz="-0.00043475"
        izz="0.0075828" />
    </inertial>
    <visual>
      <origin
        xyz="0 0 0"
        rpy="0 0 0" />
      <geometry>
        <mesh
          filename="package://mz07l/meshes/Link4.STL" />
      </geometry>
      <material
        name="">
        <color
          rgba="1 1 1 1" />
      </material>
    </visual>
    <collision>
      <origin
        xyz="0 0 0"
        rpy="0 0 0" />
      <geometry>
        <mesh
          filename="package://mz07l/meshes/Link4.STL" />
      </geometry>
    </collision>
  </link>
  <joint
    name="J4"
    type="revolute">
    <origin
      xyz="0.44 -0.044808 0"
      rpy="1.5708 0 1.5708" />
    <parent
      link="Link3" />
    <child
      link="Link4" />
    <axis
      xyz="0 0 -1" />
    <limit
      lower="-3.32"
      upper="3.32"
      effort="100"
      velocity="9.60" />
  </joint>
  <link
    name="Link5">
    <inertial>
      <origin
        xyz="0.023041 2.0859E-05 -0.0044785"
        rpy="0 0 0" />
      <mass
        value="0.39428" />
      <inertia
        ixx="0.00041541"
        ixy="-1.4643E-08"
        ixz="-4.174E-05"
        iyy="0.00053836"
        iyz="-6.3077E-07"
        izz="0.00049121" />
    </inertial>
    <visual>
      <origin
        xyz="0 0 0"
        rpy="0 0 0" />
      <geometry>
        <mesh
          filename="package://mz07l/meshes/Link5.STL" />
      </geometry>
      <material
        name="">
        <color
          rgba="1 1 1 1" />
      </material>
    </visual>
    <collision>
      <origin
        xyz="0 0 0"
        rpy="0 0 0" />
      <geometry>
        <mesh
          filename="package://mz07l/meshes/Link5.STL" />
      </geometry>
    </collision>
  </link>
  <joint
    name="J5"
    type="revolute">
    <origin
      xyz="0 0 0"
      rpy="1.5708 -1.5708 0" />
    <parent
      link="Link4" />
    <child
      link="Link5" />
    <axis
      xyz="0 0 -1" />
    <limit
      lower="-2.09"
      upper="2.09"
      effort="100"
      velocity="9.60" />
  </joint>
  <link
    name="Link6">
    <inertial>
      <origin
        xyz="-0.000274577916602459 -7.35966871450722E-05 0.0700828201728696"
        rpy="0 0 0" />
      <mass
        value="0.0303019455167" />
      <inertia
        ixx="1.15411094306873E-05"
        ixy="7.12452260823137E-08"
        ixz="-9.29996448151996E-09"
        iyy="1.10884218603645E-05"
        iyz="-2.48005623844806E-09"
        izz="2.14713719931202E-05" />
    </inertial>
    <visual>
      <origin
        xyz="0 0 0"
        rpy="0 0 0" />
      <geometry>
        <mesh
          filename="package://mz07l/meshes/Link6.STL" />
      </geometry>
      <material
        name="">
        <color
          rgba="1 1 1 1" />
      </material>
    </visual>
    <collision>
      <origin
        xyz="0 0 0"
        rpy="0 0 0" />
      <geometry>
        <mesh
          filename="package://mz07l/meshes/Link6.STL" />
      </geometry>
    </collision>
  </link>
  <joint
    name="J6"
    type="revolute">
    <origin
      xyz="0 0 0"
      rpy="1.5708 0 1.5708" />
    <parent
      link="Link5" />
    <child
      link="Link6" />
    <axis
      xyz="0 0 -1" />
    <limit
      lower="-6.28"
      upper="6.28"
      effort="100"
      velocity="17.5" />
  </joint>
  <link
    name="Tools">
    <inertial>
      <origin
        xyz="-0.00027457791660368 -7.35966871449611E-05 -0.00291717982713169"
        rpy="0 0 0" />
      <mass
        value="0.0303019455167" />
      <inertia
        ixx="1.15411094306873E-05"
        ixy="7.12452260822958E-08"
        ixz="-9.29996448151563E-09"
        iyy="1.10884218603645E-05"
        iyz="-2.48005623844378E-09"
        izz="2.14713719931202E-05" />
    </inertial>
    <visual>
      <origin
        xyz="0 0 0"
        rpy="0 0 0" />
      <geometry>
        <mesh
          filename="package://mz07l/meshes/Tools.STL" />
      </geometry>
      <material
        name="">
        <color
          rgba="1 1 1 1" />
      </material>
    </visual>
    <collision>
      <origin
        xyz="0 0 0"
        rpy="0 0 0" />
      <geometry>
        <mesh
          filename="package://mz07l/meshes/Tools.STL" />
      </geometry>
    </collision>
  </link>
  <joint
    name="J7"
    type="fixed">
    <origin
      xyz="0 0 0.073"
      rpy="0 0 0" />
    <parent
      link="Link6" />
    <child
      link="Tools" />
    <axis
      xyz="0 0 0" />
  </joint>
</robot>